Workbook

Sheet INICIO
B2: Índice de Precios al Consumidor - IPC (Base 2016=100)
B3: Índice de Alimentos de Bolivia, Variación Porcentual Mensual, Variación Porcentual Acumulada, Variación Porcentual a 12 meses SERIE: 2018 - 2026
B4: Fecha de publicación: Octubre de 2026
B8: 1 | C8: BOLIVIA
C9: Cuadro 1.1: Índice Mensual, Según Alimentos, Serie: 2018 - 2026
C10: Cuadro 1.2: Variación Porcentual Mensual, Según Alimentos, Serie: 2018 - 2026
C11: Cuadro 1.3: Variación Porcentual Acumulada, Según Alimentos, Serie: 2019 - 2026
C12: Cuadro 1.4: Variación Porcentual a 12 Meses, Según Alimentos, Serie: 2019 - 2026
B15: Índice de Precios al Consumidor El Índice de Precios al Consumidor (IPC) es un indicador que mide la variación mensual de los precios de un conjunto de bienes y servicios, representativos del gasto que realizan los hogares. El IPC con base 2016 sustenta su estructura en una canasta representativa del conjunto de bienes y servicios que consumen los hogares, su alcance comprende a seis ciudades capitales del país (Sucre, Oruro, Potosí, Tarija, Trinidad y Cobija) y tres conurbaciones: Conurbación La Paz (Nuestra Señora de La Paz, El Alto, Viacha y Achocalla), Región Metropolitana Kanata (Cercado, Quillacollo, Sacaba, Colcapirhua, Tiquipaya, Sipe Sipe y Vinto) y Conurbación Santa Cruz (Santa Cruz de la Sierra, La Guardia, Cotoca y Warnes). Número índice: Un índice es una variable estadística. El número índice corresponde al valor que toma la variable en un momento dado del tiempo. A su vez, es la expresión numérica que muestra los cambios de una magnitud en el tiempo. Para la construcción de un número índice es necesario definir su cobertura, período de base y sistema de ponderación, entre otros. “En general, se considera que el IPC es un índice que mide los cambios en los precios de los bienes y servicios de consumo adquiridos y utilizados por los hogares”1 Variación porcentual mensual: La variación mensual de un índice es la variación promedio de los precios de un mes a otro; se calcula como el cociente entre el índice en el mes corriente t y el índice en el mes anterior t-1, según la siguiente fórmula: Variación (%) Mensual t = [(IPCt ⁄ IPCt-1) -1]*100. Variación porcentual acumulada: Es la variación promedio de los precios en el año y se calcula como cociente entre el índice en el mes t y el índice de diciembre del año anterior, según la siguiente fórmula: Variación (%) Acumulada t = [(IPCt ⁄ IPCdic año anterior)-1]*100. Variación porcentual a 12 meses: Es la variación promedio de los precios entre el mes de referencia y el mismo mes del año inmediatamente anterior, según la siguiente fórmula: Variación (%) 12 meses t = [(IPCmes t ⁄ IPCmes t, año anterior) -1]*100. Es importante mencionar que estas fórmulas para calcular variaciones también son aplicables a los índices de ciudades capitales y conurbaciones, índices a nivel división e índices de productos. _______________________________________________ 1 Manual del Índice de Precios al Consumidor – Teoría y Práctica, párrafo 1.150, Pág. 21.

Sheet 1 - BOLIVIA
A2: Cuadro Nº 1.1
A3: BOLIVIA: ÍNDICE DE PRECIOS AL CONSUMIDOR MENSUAL, GRUPO DE ALIMENTOS, 2018 - 2026
A4: (Base 2016=100)
A5: MES | B5: 2018 | C5: 2019 | D5: 2020 | E5: 2021 | F5: 2022 | G5: 2023 | H5: 2024 | I5: 2025 | J5: 2026
A7: Enero | B7: 101.87225 | C7: 103.37426 | D7: 105.29606 | E7: 106.04381 | F7: 106.47671 | G7: 112.09053 | H7: 114.19698 | I7: 132.45929 | J7: 162.0509
A8: Febrero | B8: 102.27879 | C8: 103.08134 | D8: 105.15026 | E8: 106.12359 | F8: 106.68166 | G8: 110.88191 | H8: 114.25204 | I8: 134.45178 | J8: 160.53946
A9: Marzo | B9: 102.04549 | C9: 102.85379 | D9: 105.41771 | E9: 106.23616 | F9: 106.35999 | G9: 110.67908 | H9: 114.84298 | I9: 138.47554 | J9: 160.11195
A10: Abril | B10: 101.6369 | C10: 103.17204 | D10: 105.86073 | E10: 106.23295 | F10: 106.1831 | G10: 110.99305 | H10: 116.07942 | I10: 139.39522 | J10: 160.89823
A11: Mayo | B11: 101.78718 | C11: 104.22581 | D11: 105.22786 | E11: 106.09887 | F11: 107.05376 | G11: 112.24112 | H11: 117.22144 | I11: 145.06872 | J11: 168.31991
A12: Junio | B12: 101.98732 | C12: 104.52082 | D12: 105.77518 | E12: 106.0016 | F12: 107.91521 | G12: 112.5432 | H12: 118.15531 | I12: 155.3509 | J12: 175.85495
A13: Julio | B13: 101.90275 | C13: 104.96215 | D13: 105.76412 | E13: 106.36617 | F13: 108.43553 | G13: 112.97815 | H13: 118.37002 | I13: 155.86898 | J13: 164.13531
A14: Agosto | B14: 102.31971 | C14: 106.37751 | D14: 107.0641 | E14: 107.57374 | F14: 108.61286 | G14: 113.92815 | H14: 120.24539 | I14: 157.77922 | J14: 166.48965
A15: Septiembre | B15: 102.08074 | C15: 106.2289 | D15: 104.6632 | E15: 106.92561 | F15: 108.94848 | G15: 113.64614 | H15: 121.20722 | I15: 158.53749 | J15: 167.75564
A16: Octubre | B16: 102.52902 | C16: 107.34941 | D16: 105.66112 | E16: 106.12178 | F16: 110.58477 | G16: 113.60664 | H16: 124.59858 | I16: 161.00235
A17: Noviembre | B17: 102.87036 | C17: 109.93262 | D17: 105.35023 | E17: 106.38548 | F17: 111.58288 | G17: 113.59688 | H17: 127.57129 | I17: 163.5058
A18: Diciembre | B18: 103.30248 | C18: 105.67037 | D18: 105.58652 | E18: 106.14048 | F18: 111.45212 | G18: 114.45669 | H18: 129.32683 | I18: 161.89341
A19: Fuente: Instituto Nacional de Estadística
A20: Nota: El grupo de Alimentos, está clasificado por alimentos y bebidas consumidas dentro y fuera del hogar, comprendidas entre las divisiones: 1 (alimentos y bebidas no alcohólicas), 2 (Bebidas alcohólicas y tabaco, excepto el cigarrillo), 9 (Recreación y cultura, solo ingresa alimentos para animales domésticos) y 11 (Alimentos y bebidas consumidas fuera del hogar).
A22: Cuadro Nº 1.2
A23: BOLIVIA: VARIACIÓN PORCENTUAL MENSUAL Y ACUMULADA DEL ÍNDICE DE PRECIOS AL CONSUMIDOR, GRUPO DE ALIMENTOS, 2018 - 2026
A24: (Porcentaje)
A25: MES | B25: 2018 | C25: 2019 | D25: 2020 | E25: 2021 | F25: 2022 | G25: 2023 | H25: 2024 | I25: 2025 | J25: 2026
A27: Enero | B27: 0.74819786 | C27: 0.069482248 | D27: -0.3542228 | E27: 0.43309656 | F27: 0.31678524 | G27: 0.57281022 | H27: -0.22691463 | I27: 2.4221255 | J27: 0.097277991
A28: Febrero | B28: 0.3990699 | C28: -0.28335965 | D28: -0.13846544 | E28: 0.075233042 | F28: 0.19248426 | G28: -1.0782495 | H28: 0.048222364 | I28: 1.5042232 | J28: -0.93269557
A29: Marzo | B29: -0.22810185 | C29: -0.22074367 | D29: 0.2543466 | E29: 0.10607243 | F29: -0.30152634 | G29: -0.18292778 | H29: 0.51722027 | I29: 2.9927214 | J29: -0.26629334
A30: Abril | B30: -0.40039626 | C30: 0.30942483 | D30: 0.42025759 | E30: -0.0030209265 | F30: -0.16631193 | G30: 0.28368007 | H30: 1.0766371 | I30: 0.6641437 | J30: 0.49107796
A31: Mayo | B31: 0.14786082 | C31: 1.0213629 | D31: -0.59783365 | E31: -0.12621525 | F31: 0.81995566 | G31: 1.1244526 | H31: 0.98382812 | I31: 4.0700858 | J31: 4.6126596
A32: Junio | B32: 0.1966214 | C32: 0.28304945 | D32: 0.52013028 | E32: -0.091678703 | F32: 0.80469181 | G32: 0.26914181 | H32: 0.79666903 | I32: 7.0877953 | J32: 4.4766167
A33: Julio | B33: -0.082919198 | C33: 0.42224733 | D33: -0.010462833 | E33: 0.34393596 | F33: 0.48215981 | G33: 0.38647085 | H33: 0.18172175 | I33: 0.33348893 | J33: -6.6643781
A34: Agosto | B34: 0.40917381 | C34: 1.3484428 | D34: 1.2291328 | E34: 1.1352877 | F34: 0.16353241 | G34: 0.84086836 | H34: 1.5843227 | I34: 1.2255467 | J34: 1.4343859
A35: Septiembre | B35: -0.23354876 | C35: -0.13969626 | D35: -2.2424883 | E35: -0.60249125 | F35: 0.30900458 | G35: -0.2475308 | H35: 0.79989187 | I35: 0.48058395 | J35: 0.76040276
A36: Octubre | B36: 0.4391366 | C36: 1.054808 | D36: 0.95346202 | E36: -0.75177259 | F36: 1.5018946 | G36: -0.034753747 | H36: 2.7979861 | I36: 1.5547522
A37: Noviembre | B37: 0.3329203 | C37: 2.4063512 | D37: -0.29423386 | E37: 0.24849572 | F37: 0.90257556 | G37: -0.0085911744 | H37: 2.3858282 | I37: 1.5549126
A38: Diciembre | B38: 0.42006331 | C38: -3.8771466 | D38: 0.22428679 | E38: -0.2303013 | F38: -0.11718962 | G38: 0.75689564 | H38: 1.3761286 | I38: -0.98613224
A39: ACUMULADA | B39: 2.162649 | C39: 2.2921896 | D39: -0.079350636 | E39: 0.52464911 | F39: 5.0043504 | G39: 2.6958453 | H39: 12.991935 | I39: 25.18161
A40: Fuente: Instituto Nacional de Estadística
A41: Nota: El grupo de Alimentos, está clasificado por alimentos y bebidas consumidas dentro y fuera del hogar, comprendidas entre las divisiones: 1 (alimentos y bebidas no alcohólicas), 2 (Bebidas alcohólicas y tabaco, excepto el cigarrillo), 9 (Recreación y cultura, solo ingresa alimentos para animales domésticos) y 11 (Alimentos y bebidas consumidas fuera del hogar).
A43: Cuadro Nº 1.3
A44: BOLIVIA: VARIACIÓN PORCENTUAL ACUMULADA MENSUAL DEL ÍNDICE DE PRECIOS AL CONSUMIDOR, GRUPO DE ALIMENTOS, 2018 - 2026
A45: (Porcentaje)
...

Sheet Indices iniciales
B1: COICOP | C1: codart | D1: Codigo | E1: Peso | F1: 39814 | G1: 39845 | H1: 39873 | I1: 39904 | J1: 39934 | K1: 39965 | L1: 39995 | M1: 40026 | N1: 40057 | O1: 40087 | P1: 40118 | Q1: 40148 | R1: 40179 | S1: 40210 | T1: 40238 | U1: 40269 | V1: 40299 | W1: 40330 | X1: 40360 | Y1: 40391 | Z1: 40422 | AA1: 40452 | AB1: 40483 | AC1: 40513 | AD1: 40544 | AE1: 40575 | AF1: 40603 | AG1: 40634 | AH1: 40664 | AI1: 40695 | AJ1: 40725 | AK1: 40756 | AL1: 40787 | AM1: 40817 | AN1: 40848 | AO1: 40878 | AP1: 40909 | AQ1: 40940 | AR1: 40969 | AS1: 41000 | AT1: 41030 | AU1: 41061 | AV1: 41091 | AW1: 41122 | AX1: 41153 | AY1: 41183 | AZ1: 41214 | BA1: 41244 | BB1: 41275 | BC1: 41306 | BD1: 41334 | BE1: 41365 | BF1: 41395 | BG1: 41426 | BH1: 41456 | BI1: 41487 | BJ1: 41518 | BK1: 41548 | BL1: 41579 | BM1: 41609 | BN1: 41640 | BO1: 41671 | BP1: 41699 | BQ1: 41730 | BR1: 41760
B2: 0111 | C2: 1110100 | D2: =+C2*1 -> 1110100 | E2: 1.730377 | F2: 100.5045 | G2: 98.818477 | H2: 96.568144 | I2: 95.26 | J2: 94.975811 | K2: 90.699792 | L2: 85.653038 | M2: 82.700853 | N2: 79.706935 | O2: 78.174141 | P2: 78.111155 | Q2: 77.73063 | R2: 77.661983 | S2: 78.487311 | T2: 78.416193 | U2: 77.108891 | V2: 77.159298 | W2: 77.843819 | X2: 77.744343 | Y2: 77.480921 | Z2: 77.49216 | AA2: 78.016429 | AB2: 81.6897 | AC2: 84.624129 | AD2: 85.580076 | AE2: 86.185942 | AF2: 86.275216 | AG2: 86.68663 | AH2: 90.15374 | AI2: 91.788964 | AJ2: 90.786235 | AK2: 87.936973 | AL2: 86.590842 | AM2: 87.155241 | AN2: 86.99173 | AO2: 87.166698 | AP2: 87.257136 | AQ2: 87.017039 | AR2: 86.906608 | AS2: 91.964291 | AT2: 100.9265 | AU2: 102.91829 | AV2: 100.68779 | AW2: 99.965915 | AX2: 99.772733 | AY2: 100.89131 | AZ2: 102.47068 | BA2: 102.68206 | BB2: 101.91076 | BC2: 97.642614 | BD2: 94.375971 | BE2: 93.450787 | BF2: 92.958099 | BG2: 92.507274 | BH2: 91.806044 | BI2: 90.480462 | BJ2: 89.647315 | BK2: 89.498182 | BL2: 89.387668 | BM2: 89.134365 | BN2: 89.02362 | BO2: 88.993725 | BP2: 88.72464 | BQ2: 88.596481 | BR2: 88.781025
B3: 0111 | C3: 1110200 | D3: =+C3*1 -> 1110200 | E3: 0.11976699 | F3: 102.57874 | G3: 104.05331 | H3: 103.57701 | I3: 103.01 | J3: 102.27329 | K3: 100.99861 | L3: 100.35088 | M3: 99.654429 | N3: 99.46223 | O3: 99.146512 | P3: 99.287799 | Q3: 98.538366 | R3: 98.291327 | S3: 97.651525 | T3: 97.342884 | U3: 97.110258 | V3: 96.720186 | W3: 96.421241 | X3: 95.929145 | Y3: 94.908191 | Z3: 94.506541 | AA3: 94.370357 | AB3: 94.696047 | AC3: 96.180123 | AD3: 97.455652 | AE3: 97.749967 | AF3: 98.007804 | AG3: 98.647091 | AH3: 99.799875 | AI3: 100.61413 | AJ3: 100.67678 | AK3: 100.91074 | AL3: 100.84194 | AM3: 101.73886 | AN3: 103.66114 | AO3: 107.26976 | AP3: 108.81319 | AQ3: 109.42665 | AR3: 109.39051 | AS3: 109.2774 | AT3: 110.25454 | AU3: 110.70342 | AV3: 109.60895 | AW3: 109.9165 | AX3: 109.71426 | AY3: 109.48927 | AZ3: 108.88409 | BA3: 108.75229 | BB3: 109.43504 | BC3: 108.77962 | BD3: 107.94567 | BE3: 107.8205 | BF3: 107.33759 | BG3: 106.92543 | BH3: 106.70959 | BI3: 106.89632 | BJ3: 106.67534 | BK3: 105.81379 | BL3: 104.2972 | BM3: 104.2439 | BN3: 104.48199 | BO3: 104.19171 | BP3: 103.70149 | BQ3: 104.0008 | BR3: 103.85017
B4: 0111 | C4: 1110300 | D4: =+C4*1 -> 1110300 | E4: 0.25776414 | F4: 100.43903 | G4: 100.47536 | H4: 100.61988 | I4: 100.58 | J4: 100.47203 | K4: 100.33086 | L4: 100.60361 | M4: 104.45934 | N4: 106.08933 | O4: 106.4279 | P4: 106.31423 | Q4: 106.85598 | R4: 107.16005 | S4: 107.55693 | T4: 107.21121 | U4: 106.9373 | V4: 107.47968 | W4: 107.66005 | X4: 107.65147 | Y4: 107.10451 | Z4: 107.35803 | AA4: 107.02633 | AB4: 106.98536 | AC4: 107.63141 | AD4: 108.32259 | AE4: 108.1404 | AF4: 108.54977 | AG4: 108.82078 | AH4: 111.8566 | AI4: 112.69359 | AJ4: 112.6825 | AK4: 111.67883 | AL4: 110.85118 | AM4: 110.32022 | AN4: 110.03891 | AO4: 109.68048 | AP4: 109.9326 | AQ4: 110.13021 | AR4: 112.14728 | AS4: 113.18511 | AT4: 113.6391 | AU4: 114.2147 | AV4: 113.96779 | AW4: 114.51875 | AX4: 114.25118 | AY4: 114.42504 | AZ4: 113.66003 | BA4: 114.47146 | BB4: 114.4988 | BC4: 112.87059 | BD4: 112.62566 | BE4: 112.38797 | BF4: 113.12559 | BG4: 113.47467 | BH4: 113.82802 | BI4: 113.64965 | BJ4: 113.61351 | BK4: 114.30411 | BL4: 114.10888 | BM4: 113.77056 | BN4: 114.05275 | BO4: 114.03614 | BP4: 113.91912 | BQ4: 114.44853 | BR4: 114.34096
B5: 0111 | C5: 1110400 | D5: =+C5*1 -> 1110400 | E5: 0.11222784 | F5: 100.22332 | G5: 100.4129 | H5: 100.56317 | I5: 101.09 | J5: 101.16492 | K5: 101.16389 | L5: 101.55259 | M5: 104.61643 | N5: 105.31123 | O5: 105.23436 | P5: 103.88237 | Q5: 102.83219 | R5: 103.39856 | S5: 103.63619 | T5: 102.93378 | U5: 102.97761 | V5: 103.2244 | W5: 105.46781 | X5: 105.52208 | Y5: 105.61011 | Z5: 105.51173 | AA5: 104.29999 | AB5: 105.69019 | AC5: 106.09877 | AD5: 106.27493 | AE5: 106.32601 | AF5: 105.79742 | AG5: 105.94103 | AH5: 105.85421 | AI5: 105.98381 | AJ5: 106.04051 | AK5: 106.48957 | AL5: 107.17089 | AM5: 107.33897 | AN5: 107.37667 | AO5: 106.71093 | AP5: 107.30018 | AQ5: 107.50116 | AR5: 107.61227 | AS5: 108.22844 | AT5: 108.36173 | AU5: 108.99013 | AV5: 109.1932 | AW5: 108.82827 | AX5: 112.20968 | AY5: 112.7322 | AZ5: 112.63111 | BA5: 112.68035 | BB5: 113.11178 | BC5: 113.64932 | BD5: 113.48996 | BE5: 113.90993 | BF5: 113.58362 | BG5: 113.36436 | BH5: 112.97984 | BI5: 113.17272 | BJ5: 113.27141 | BK5: 113.72556 | BL5: 114.36063 | BM5: 114.62613 | BN5: 115.0738 | BO5: 114.28359 | BP5: 114.87399 | BQ5: 114.9581 | BR5: 114.88551
B6: 0111 | C6: 1110500 | D6: =+C6*1 -> 1110500 | E6: 0.074850151 | F6: 101.72063 | G6: 102.55109 | H6: 102.99042 | I6: 102.8 | J6: 102.84823 | K6: 101.92471 | L6: 102.37186 | M6: 103.0102 | N6: 103.50601 | O6: 103.54557 | P6: 103.94206 | Q6: 103.21109 | R6: 103.68436 | S6: 103.41091 | T6: 102.23995 | U6: 102.10352 | V6: 101.16237 | W6: 100.72759 | X6: 100.56913 | Y6: 100.04614 | Z6: 100.19836 | AA6: 99.924414 | AB6: 99.733183 | AC6: 100.32263 | AD6: 100.56425 | AE6: 100.33982 | AF6: 100.47692 | AG6: 99.626203 | AH6: 99.911868 | AI6: 100.25661 | AJ6: 99.841506 | AK6: 101.27193 | AL6: 102.38327 | AM6: 102.91921 | AN6: 103.07492 | AO6: 103.64964 | AP6: 105.23614 | AQ6: 106.52901 | AR6: 106.43666 | AS6: 106.11475 | AT6: 106.80942 | AU6: 107.04072 | AV6: 107.24135 | AW6: 107.63086 | AX6: 107.79104 | AY6: 108.08852 | AZ6: 108.45062 | BA6: 108.91498 | BB6: 109.04554 | BC6: 108.93557 | BD6: 108.27107 | BE6: 108.4112 | BF6: 107.98114 | BG6: 106.81251 | BH6: 107.30724 | BI6: 107.44128 | BJ6: 107.72363 | BK6: 108.09013 | BL6: 107.57292 | BM6: 107.66268 | BN6: 108.08942 | BO6: 108.02998 | BP6: 108.00107 | BQ6: 107.54682 | BR6: 107.93576
B7: 0111 | C7: 1120100 | D7: =+C7*1 -> 1120100 | E7: 0.87175719 | F7: 99.837864 | G7: 100.26303 | H7: 100.29745 | I7: 100.85 | J7: 100.86249 | K7: 99.884304 | L7: 99.461636 | M7: 99.813161 | N7: 99.551003 | O7: 99.827768 | P7: 99.342997 | Q7: 99.525143 | R7: 98.502504 | S7: 99.825822 | T7: 99.823248 | U7: 100.41417 | V7: 101.30898 | W7: 101.43559 | X7: 100.61959 | Y7: 100.55991 | Z7: 100.33173 | AA7: 101.10654 | AB7: 101.29981 | AC7: 101.97379 | AD7: 101.6546 | AE7: 102.16375 | AF7: 103.08757 | AG7: 103.1279 | AH7: 103.63148 | AI7: 102.47419 | AJ7: 104.03853 | AK7: 104.62178 | AL7: 104.08254 | AM7: 104.21982 | AN7: 103.89253 | AO7: 103.80324 | AP7: 104.17238 | AQ7: 104.11605 | AR7: 105.45929 | AS7: 106.78206 | AT7: 107.10862 | AU7: 107.28986 | AV7: 107.75169 | AW7: 107.9142 | AX7: 108.52128 | AY7: 108.57442 | AZ7: 107.16441 | BA7: 107.69018 | BB7: 107.98762 | BC7: 107.99921 | BD7: 108.08687 | BE7: 108.72598 | BF7: 108.54552 | BG7: 108.67982 | BH7: 109.04118 | BI7: 108.92297 | BJ7: 109.48192 | BK7: 109.36006 | BL7: 108.9621 | BM7: 110.05105 | BN7: 109.56126 | BO7: 109.8202 | BP7: 110.56143 | BQ7: 110.26124 | BR7: 110.89663
B8: 0111 | C8: 1120200 | D8: =+C8*1 -> 1120200 | E8: 0.58417563 | F8: 101.05798 | G8: 102.12237 | H8: 102.19199 | I8: 101.91 | J8: 101.69319 | K8: 102.16773 | L8: 101.76998 | M8: 102.04221 | N8: 102.56043 | O8: 102.34695 | P8: 102.41415 | Q8: 103.22646 | R8: 103.31605 | S8: 103.30247 | T8: 103.0808 | U8: 103.50699 | V8: 104.11922 | W8: 104.37998 | X8: 103.61541 | Y8: 104.15088 | Z8: 103.89456 | AA8: 104.34962 | AB8: 103.85114 | AC8: 104.62663 | AD8: 104.74899 | AE8: 104.71904 | AF8: 105.78877 | AG8: 106.81082 | AH8: 107.79709 | AI8: 108.58498 | AJ8: 108.1773 | AK8: 108.55222 | AL8: 108.76905 | AM8: 109.70521 | AN8: 110.23529 | AO8: 111.29035 | AP8: 112.27555 | AQ8: 111.94006 | AR8: 112.3575 | AS8: 112.34306 | AT8: 113.08668 | AU8: 113.23571 | AV8: 112.68878 | AW8: 113.37355 | AX8: 113.19448 | AY8: 113.08223 | AZ8: 112.66171 | BA8: 114.41103 | BB8: 115.56642 | BC8: 115.51867 | BD8: 114.90382 | BE8: 114.91551 | BF8: 115.0143 | BG8: 115.06745 | BH8: 115.36498 | BI8: 116.35521 | BJ8: 116.572 | BK8: 117.10352 | BL8: 116.78725 | BM8: 117.54672 | BN8: 117.60297 | BO8: 117.75236 | BP8: 117.54324 | BQ8: 117.38544 | BR8: 117.4245
B9: 0112 | C9: 1510100 | D9: =+C9*1 -> 1510100 | E9: 2.4776955 | F9: 100.93473 | G9: 101.30026 | H9: 101.63555 | I9: 102.44 | J9: 103.3567 | K9: 103.63609 | L9: 103.6651 | M9: 102.94244 | N9: 101.06507 | O9: 97.643306 | P9: 95.917891 | Q9: 94.655256 | R9: 93.501209 | S9: 92.791375 | T9: 93.037301 | U9: 94.945037 | V9: 95.140482 | W9: 95.624806 | X9: 94.836742 | Y9: 94.747212 | Z9: 94.191853 | AA9: 93.577952 | AB9: 92.974109 | AC9: 93.506038 | AD9: 96.09717 | AE9: 96.083175 | AF9: 96.223057 | AG9: 95.33649 | AH9: 95.817782 | AI9: 94.81839 | AJ9: 93.713386 | AK9: 93.044184 | AL9: 94.080543 | AM9: 93.85499 | AN9: 93.804236 | AO9: 94.080311 | AP9: 95.244861 | AQ9: 96.259405 | AR9: 96.32182 | AS9: 97.055931 | AT9: 99.187454 | AU9: 99.383818 | AV9: 99.178154 | AW9: 99.850263 | AX9: 98.851048 | AY9: 98.866014 | AZ9: 99.134721 | BA9: 99.613514 | BB9: 99.776947 | BC9: 99.279694 | BD9: 99.878895 | BE9: 100.90645 | BF9: 102.64746 | BG9: 103.25056 | BH9: 102.84418 | BI9: 102.87312 | BJ9: 102.80706 | BK9: 102.89572 | BL9: 102.41407 | BM9: 102.86157 | BN9: 103.26969 | BO9: 103.64794 | BP9: 103.90342 | BQ9: 104.06433 | BR9: 106.17493
B10: 0112 | C10: 1510200 | D10: =+C10*1 -> 1510200 | E10: 0.50415634 | F10: 100.7489 | G10: 99.629778 | H10: 98.562135 | I10: 97.61 | J10: 93.763102 | K10: 90.376676 | L10: 89.544776 | M10: 92.540699 | N10: 93.652441 | O10: 92.317885 | P10: 91.996467 | Q10: 93.74394 | R10: 94.147586 | S10: 94.146064 | T10: 93.187905 | U10: 93.743038 | V10: 92.415716 | W10: 91.128673 | X10: 91.968422 | Y10: 92.532843 | Z10: 91.339847 | AA10: 91.918813 | AB10: 92.297889 | AC10: 94.700422 | AD10: 97.009872 | AE10: 96.079316 | AF10: 95.128639 | AG10: 93.169808 | AH10: 91.99466 | AI10: 90.822564 | AJ10: 88.983128 | AK10: 88.644493 | AL10: 91.125811 | AM10: 91.489416 | AN10: 92.271613 | AO10: 93.992178 | AP10: 94.097706 | AQ10: 93.385656 | AR10: 91.878557 | AS10: 91.12801 | AT10: 90.402798 | AU10: 89.216301 | AV10: 89.732166 | AW10: 89.905109 | AX10: 91.287468 | AY10: 91.692819 | AZ10: 90.930197 | BA10: 93.131315 | BB10: 93.69992 | BC10: 92.260768 | BD10: 91.297543 | BE10: 94.324455 | BF10: 91.992451 | BG10: 94.373304 | BH10: 94.179327 | BI10: 96.425334 | BJ10: 96.497955 | BK10: 96.706605 | BL10: 95.882807 | BM10: 98.621796 | BN10: 98.016269 | BO10: 99.049953 | BP10: 99.171847 | BQ10: 99.059497 | BR10: 100.73998
B11: 0112 | C11: 1510300 | D11: =+C11*1 -> 1510300 | E11: 1.3065731 | F11: 101.19453 | G11: 101.44116 | H11: 101.07851 | I11: 100.79 | J11: 100.75292 | K11: 100.8731 | L11: 102.56641 | M11: 103.98823 | N11: 104.60836 | O11: 104.51769 | P11: 103.82258 | Q11: 103.78676 | R11: 103.64881 | S11: 103.27781 | T11: 102.28835 | U11: 102.17829 | V11: 102.29481 | W11: 102.47834 | X11: 101.72477 | Y11: 100.76541 | Z11: 100.71975 | AA11: 100.56747 | AB11: 99.642231 | AC11: 101.49616 | AD11: 103.5277 | AE11: 103.4704 | AF11: 103.41844 | AG11: 103.29698 | AH11: 103.39798 | AI11: 103.46417 | AJ11: 103.76364 | AK11: 105.39117 | AL11: 109.18206 | AM11: 112.95262 | AN11: 114.10069 | AO11: 116.21799 | AP11: 117.20616 | AQ11: 117.26652 | AR11: 115.59294 | AS11: 114.16415 | AT11: 112.51955 | AU11: 111.30239 | AV11: 111.75474 | AW11: 113.02525 | AX11: 114.61281 | AY11: 113.71795 | AZ11: 113.13045 | BA11: 113.87554 | BB11: 114.38354 | BC11: 114.60922 | BD11: 114.18997 | BE11: 114.80778 | BF11: 115.20069 | BG11: 116.06971 | BH11: 116.24314 | BI11: 116.44287 | BJ11: 115.87509 | BK11: 115.12258 | BL11: 114.32857 | BM11: 114.38394 | BN11: 114.53612 | BO11: 114.00752 | BP11: 114.14247 | BQ11: 113.51589 | BR11: 114.81319
B12: 0112 | C12: 1520100 | D12: =+C12*1 -> 1520100 | E12: 0.48856043 | F12: 100.35033 | G12: 100.29329 | H12: 100.10309 | I12: 99.77 | J12: 102.58451 | K12: 103.11317 | L12: 103.31261 | M12: 103.78749 | N12: 103.87145 | O12: 103.83601 | P12: 104.09628 | Q12: 104.1783 | R12: 104.7463 | S12: 104.69427 | T12: 105.03116 | U12: 104.77428 | V12: 105.18639 | W12: 104.69666 | X12: 104.72582 | Y12: 105.21627 | Z12: 105.47978 | AA12: 105.68727 | AB12: 105.8004 | AC12: 106.09707 | AD12: 106.19756 | AE12: 105.9322 | AF12: 105.83844 | AG12: 105.46364 | AH12: 105.22469 | AI12: 105.3668 | AJ12: 105.0302 | AK12: 104.84751 | AL12: 106.21649 | AM12: 106.74443 | AN12: 107.12456 | AO12: 107.15922 | AP12: 107.67223 | AQ12: 107.26443 | AR12: 107.12117 | AS12: 107.29537 | AT12: 107.09128 | AU12: 107.31568 | AV12: 105.04651 | AW12: 104.13733 | AX12: 103.97685 | AY12: 104.21373 | AZ12: 104.03738 | BA12: 103.98594 | BB12: 106.75204 | BC12: 107.62786 | BD12: 107.62349 | BE12: 107.5921 | BF12: 107.42039 | BG12: 107.406 | BH12: 107.63336 | BI12: 107.41112 | BJ12: 109.50085 | BK12: 110.75055 | BL12: 110.59407 | BM12: 110.76644 | BN12: 110.95317 | BO12: 110.63199 | BP12: 110.57587 | BQ12: 110.41955 | BR12: 110.51421
B13: 0113 | C13: 1610100 | D13: =+C13*1 -> 1610100 | E13: 0.57677316 | F13: 101.65207 | G13: 103.90746 | H13: 104.96566 | I13: 105.82 | J13: 106.73578 | K13: 107.19096 | L13: 107.07579 | M13: 106.98126 | N13: 107.13715 | O13: 106.87346 | P13: 106.40356 | Q13: 106.13562 | R13: 106.20532 | S13: 106.57399 | T13: 106.74128 | U13: 107.0732 | V13: 107.34875 | W13: 107.87996 | X13: 107.83652 | Y13: 107.97546 | Z13: 107.8739 | AA13: 107.66989 | AB13: 107.05532 | AC13: 107.34822 | AD13: 107.66818 | AE13: 107.11451 | AF13: 107.20291 | AG13: 107.02921 | AH13: 106.71584 | AI13: 106.49809 | AJ13: 107.19672 | AK13: 107.41862 | AL13: 107.37417 | AM13: 107.99618 | AN13: 108.57965 | AO13: 109.71861 | AP13: 110.74026 | AQ13: 110.75996 | AR13: 110.81455 | AS13: 111.41958 | AT13: 111.36321 | AU13: 111.9921 | AV13: 111.9958 | AW13: 112.91381 | AX13: 113.06302 | AY13: 112.85324 | AZ13: 112.39126 | BA13: 112.60083 | BB13: 112.72213 | BC13: 113.77346 | BD13: 113.33882 | BE13: 114.07162 | BF13: 113.85927 | BG13: 114.90949 | BH13: 115.36807 | BI13: 116.4888 | BJ13: 117.13278 | BK13: 117.41543 | BL13: 117.44673 | BM13: 116.95328 | BN13: 116.95439 | BO13: 117.77741 | BP13: 118.07231 | BQ13: 119.02251 | BR13: 119.42353
... B182: 1270 | C182: 5220100 | D182: =+C182*1 -> 5220100 | E182: 0.12982936 | F182: 100.37094 | G182: 100.50363 | H182: 101.18297 | I182: 101.65 | J182: 101.93416 | K182: 102.12041 | L182: 102.06754 | M182: 101.93465 | N182: 101.56379 | O182: 101.29942 | P182: 101.02802 | Q182: 101.21791 | R182: 100.94871 | S182: 100.64034 | T182: 100.12819 | U182: 100.01557 | V182: 99.926594 | W182: 99.963568 | X182: 100.048 | Y182: 100.00312 | Z182: 99.678682 | AA182: 99.680841 | AB182: 99.532863 | AC182: 99.659582 | AD182: 99.399352 | AE182: 99.386072 | AF182: 99.469256 | AG182: 99.150344 | AH182: 98.996105 | AI182: 98.589095 | AJ182: 98.615693 | AK182: 98.792304 | AL182: 98.904678 | AM182: 99.182728 | AN182: 99.164514 | AO182: 98.920759 | AP182: 98.673269 | AQ182: 98.604373 | AR182: 98.436658 | AS182: 98.580796 | AT182: 98.411024 | AU182: 98.402926 | AV182: 98.038791 | AW182: 97.995491 | AX182: 97.785463 | AY182: 97.851538 | AZ182: 97.727355 | BA182: 97.759524 | BB182: 97.602106 | BC182: 97.530918 | BD182: 97.379389 | BE182: 97.827632 | BF182: 98.137618 | BG182: 98.404931 | BH182: 98.029807 | BI182: 97.963275 | BJ182: 97.831547 | BK182: 98.289366 | BL182: 98.413223 | BM182: 98.521337 | BN182: 98.422252 | BO182: 98.495867 | BP182: 98.878931 | BQ182: 98.658028 | BR182: 98.823274

Sheet Agrega a clase
A1: Etiquetas de fila | B1: Suma de Peso | C1: Suma de ene-09 | D1: Suma de feb-09 | E1: Suma de mar-09 | F1: Suma de abr-09 | G1: Suma de may-09 | H1: Suma de jun-09 | I1: Suma de jul-09 | J1: Suma de ago-09 | K1: Suma de sep-09 | L1: Suma de oct-09 | M1: Suma de nov-09 | N1: Suma de dic-09 | O1: Suma de ene-10 | P1: Suma de feb-10 | Q1: Suma de mar-10 | R1: Suma de abr-10 | S1: Suma de may-10 | T1: Suma de jun-10 | U1: Suma de jul-10 | V1: Suma de ago-10 | W1: Suma de sep-10 | X1: Suma de oct-10 | Y1: Suma de nov-10 | Z1: Suma de dic-10 | AA1: Suma de ene-11 | AB1: Suma de feb-11 | AC1: Suma de mar-11 | AD1: Suma de abr-11 | AE1: Suma de may-11 | AF1: Suma de jun-11 | AG1: Suma de jul-11 | AH1: Suma de ago-11 | AI1: Suma de sep-11 | AJ1: Suma de oct-11 | AK1: Suma de nov-11 | AL1: Suma de dic-11 | AM1: Suma de ene-12 | AN1: Suma de feb-12 | AO1: Suma de mar-12 | AP1: Suma de abr-12 | AQ1: Suma de may-12 | AR1: Suma de jun-12 | AS1: Suma de jul-12 | AT1: Suma de ago-12 | AU1: Suma de sep-12 | AV1: Suma de oct-12 | AW1: Suma de nov-12 | AX1: Suma de dic-12 | AY1: Suma de ene-13 | AZ1: Suma de feb-13 | BA1: Suma de mar-13 | BB1: Suma de abr-13 | BC1: Suma de may-13 | BD1: Suma de jun-13 | BE1: Suma de jul-13 | BF1: Suma de ago-13 | BG1: Suma de sep-13 | BH1: Suma de oct-13 | BI1: Suma de nov-13 | BJ1: Suma de dic-13 | BK1: Suma de ene-14 | BL1: Suma de feb-14 | BM1: Suma de mar-14 | BN1: Suma de abr-14 | BO1: Suma de may-14
A2: 0111 | B2: 3.7509189 | C2: 377.01744 | D2: 375.36182 | E2: 371.56852 | F2: 369.58858 | G2: 368.87702 | H2: 360.64407 | I2: 351.38029 | J2: 348.03945 | K2: 343.44526 | L2: 340.95331 | M2: 340.32654 | N2: 340.17872 | O2: 339.36855 | P2: 341.97423 | Q2: 341.42688 | R2: 339.82511 | S2: 341.10037 | T2: 342.77748 | U2: 341.38043 | V2: 340.89286 | W2: 340.58125 | X2: 342.17141 | Y2: 348.57499 | Z2: 355.12748 | AA2: 356.94363 | AB2: 358.39559 | AC2: 360.06766 | AD2: 361.51065 | AE2: 369.45743 | AF2: 372.092 | AG2: 371.4624 | AH2: 367.18635 | AI2: 364.45169 | AJ2: 366.1244 | AK2: 366.0394 | AL2: 367.18877 | AM2: 368.67732 | AN2: 368.2605 | AO2: 370.00542 | AP2: 380.20083 | AQ2: 396.72893 | AR2: 400.7105 | AS2: 396.77708 | AT2: 396.23671 | AU2: 396.62533 | AV2: 398.64042 | AW2: 399.64456 | AX2: 401.72424 | AY2: 401.47087 | AZ2: 393.62146 | BA2: 387.45555 | BB2: 386.39997 | BC2: 385.51131 | BD2: 384.80788 | BE2: 384.14243 | BF2: 382.33215 | BG2: 381.50083 | BH2: 381.60027 | BI2: 380.67796 | BJ2: 381.57554 | BK2: 381.17322 | BL2: 381.30232 | BM2: 381.33593 | BN2: 380.90804 | BO2: 381.77929
A3: 0112 | B3: 4.7769854 | C3: 482.12397 | D3: 482.7598 | E3: 482.48553 | F3: 483.45901 | G3: 485.11749 | H3: 484.51775 | I3: 486.48009 | J3: 488.28968 | K3: 485.04988 | L3: 475.7632 | M3: 470.54504 | N3: 468.2909 | O3: 465.73228 | P3: 463.4626 | Q3: 462.46065 | R3: 467.19801 | S3: 467.36666 | T3: 467.91834 | U3: 465.41878 | V3: 464.46765 | W3: 462.55926 | X3: 461.23249 | Y3: 458.77385 | Z3: 463.87029 | AA3: 474.15811 | AB3: 473.44977 | AC3: 473.20337 | AD3: 469.67735 | AE3: 470.29262 | AF3: 467.38142 | AG3: 463.94302 | AH3: 464.15145 | AI3: 473.59211 | AJ3: 478.40102 | AK3: 480.35537 | AL3: 484.69017 | AM3: 489.17053 | AN3: 491.2049 | AO3: 488.34309 | AP3: 488.00189 | AQ3: 490.66903 | AR3: 489.0767 | AS3: 488.30961 | AT3: 491.27791 | AU3: 491.49494 | AV3: 490.68291 | AW3: 490.11044 | AX3: 493.35483 | AY3: 496.06158 | AZ3: 494.82674 | BA3: 495.27585 | BB3: 500.13971 | BC3: 503.70719 | BD3: 507.53022 | BE3: 506.76323 | BF3: 508.11967 | BG3: 508.27171 | BH3: 508.22391 | BI3: 505.50132 | BJ3: 508.14753 | BK3: 509.14351 | BL3: 509.75428 | BM3: 510.59762 | BN3: 510.04463 | BO3: 517.86255
A4: 0113 | B4: 0.60482878 | C4: 61.495716 | D4: 62.831986 | E4: 63.448409 | F4: 63.93677 | G4: 64.459092 | H4: 64.727452 | I4: 64.65879 | J4: 64.597727 | K4: 64.620945 | L4: 64.547052 | M4: 64.227607 | N4: 64.084933 | O4: 64.14809 | P4: 64.372281 | Q4: 64.421562 | R4: 64.647244 | S4: 64.804584 | T4: 65.08739 | U4: 65.051807 | V4: 65.139144 | W4: 65.044755 | X4: 64.94989 | Y4: 64.571937 | Z4: 64.782054 | AA4: 64.962188 | AB4: 64.675161 | AC4: 64.746932 | AD4: 64.608317 | AE4: 64.438341 | AF4: 64.302967 | AG4: 64.734346 | AH4: 64.827411 | AI4: 64.762352 | AJ4: 65.196591 | AK4: 65.551492 | AL4: 66.15224 | AM4: 66.777341 | AN4: 66.773881 | AO4: 66.762311 | AP4: 67.178688 | AQ4: 67.101657 | AR4: 67.464126 | AS4: 67.447952 | AT4: 68.033204 | AU4: 68.143716 | AV4: 68.059639 | AW4: 67.739024 | AX4: 67.861802 | AY4: 67.921087 | AZ4: 68.480162 | BA4: 68.108859 | BB4: 68.559356 | BC4: 68.453094 | BD4: 69.061816 | BE4: 69.373194 | BF4: 70.050916 | BG4: 70.493216 | BH4: 70.687147 | BI4: 70.736538 | BJ4: 70.43988 | BK4: 70.465071 | BL4: 70.965951 | BM4: 71.167154 | BN4: 71.803045 | BO4: 72.149032
A5: 0114 | B5: 3.2817273 | C5: 328.42344 | D5: 331.41063 | E5: 331.88177 | F5: 333.63182 | G5: 333.00005 | H5: 331.15537 | I5: 329.555 | J5: 329.55798 | K5: 329.65497 | L5: 329.06773 | M5: 330.17528 | N5: 332.16957 | O5: 333.90443 | P5: 337.93786 | Q5: 339.18231 | R5: 340.10293 | S5: 339.60635 | T5: 338.84853 | U5: 338.77779 | V5: 339.22425 | W5: 339.81936 | X5: 339.01078 | Y5: 339.47551 | Z5: 341.23191 | AA5: 341.63987 | AB5: 342.85498 | AC5: 342.46193 | AD5: 342.50914 | AE5: 344.28169 | AF5: 343.85501 | AG5: 344.29872 | AH5: 346.73827 | AI5: 348.06388 | AJ5: 353.51013 | AK5: 356.01082 | AL5: 360.39304 | AM5: 364.51417 | AN5: 365.35257 | AO5: 365.58433 | AP5: 368.29357 | AQ5: 368.8768 | AR5: 364.61439 | AS5: 363.61495 | AT5: 365.10372 | AU5: 366.26072 | AV5: 369.22369 | AW5: 368.53596 | AX5: 369.18167 | AY5: 367.59697 | AZ5: 370.73679 | BA5: 370.18051 | BB5: 372.58978 | BC5: 372.37937 | BD5: 370.94407 | BE5: 369.63671 | BF5: 371.07346 | BG5: 372.98352 | BH5: 373.7909 | BI5: 373.73585 | BJ5: 373.89491 | BK5: 374.88721 | BL5: 376.87113 | BM5: 378.01665 | BN5: 380.95846 | BO5: 384.02224
A6: 0115 | B6: 1.024325 | C6: 102.60988 | D6: 102.53321 | E6: 102.23802 | F6: 103.00496 | G6: 103.55549 | H6: 104.79455 | I6: 104.91833 | J6: 105.40921 | K6: 104.37305 | L6: 103.54194 | M6: 101.69762 | N6: 101.68113 | O6: 102.12256 | P6: 101.58543 | Q6: 100.32126 | R6: 100.18196 | S6: 99.182733 | T6: 98.773121 | U6: 98.156554 | V6: 97.854606 | W6: 96.485916 | X6: 95.091106 | Y6: 94.133456 | Z6: 95.726384 | AA6: 97.567889 | AB6: 99.683757 | AC6: 100.96732 | AD6: 101.11853 | AE6: 101.96486 | AF6: 102.16112 | AG6: 102.19882 | AH6: 102.05754 | AI6: 101.00622 | AJ6: 101.25914 | AK6: 100.95196 | AL6: 101.35434 | AM6: 101.44203 | AN6: 100.27447 | AO6: 99.971716 | AP6: 100.57044 | AQ6: 100.03693 | AR6: 99.759357 | AS6: 98.873924 | AT6: 98.053576 | AU6: 97.189427 | AV6: 95.738764 | AW6: 95.286215 | AX6: 94.997314 | AY6: 95.924773 | AZ6: 95.848984 | BA6: 95.382644 | BB6: 96.075098 | BC6: 95.802998 | BD6: 95.386632 | BE6: 95.34197 | BF6: 95.541623 | BG6: 95.406812 | BH6: 93.754153 | BI6: 93.217444 | BJ6: 92.948311 | BK6: 93.273192 | BL6: 92.787409 | BM6: 93.110734 | BN6: 92.8525 | BO6: 93.04877
A7: 0116 | B7: 0.89582886 | C7: 91.313017 | D7: 94.334953 | E7: 98.422182 | F7: 98.70551 | G7: 93.610271 | H7: 91.093492 | I7: 90.145881 | J7: 90.015652 | K7: 88.748634 | L7: 87.692272 | M7: 81.093673 | N7: 77.989744 | O7: 79.308288 | P7: 85.623878 | Q7: 91.485285 | R7: 96.344938 | S7: 91.861124 | T7: 87.24285 | U7: 84.756063 | V7: 83.384509 | W7: 82.987214 | X7: 83.349222 | Y7: 84.278441 | Z7: 87.620565 | AA7: 92.500351 | AB7: 102.98177 | AC7: 109.3953 | AD7: 110.05427 | AE7: 107.67962 | AF7: 109.06364 | AG7: 114.60384 | AH7: 112.43565 | AI7: 110.77758 | AJ7: 107.87104 | AK7: 102.59186 | AL7: 99.072469 | AM7: 99.808021 | AN7: 106.03281 | AO7: 112.86709 | AP7: 111.03457 | AQ7: 102.36412 | AR7: 99.466209 | AS7: 102.03332 | AT7: 100.60601 | AU7: 100.23932 | AV7: 101.93305 | AW7: 96.892703 | AX7: 95.378988 | AY7: 97.042872 | AZ7: 100.56852 | BA7: 105.86723 | BB7: 111.36077 | BC7: 103.82185 | BD7: 100.67864 | BE7: 106.73387 | BF7: 109.59297 | BG7: 116.6036 | BH7: 111.37578 | BI7: 107.41098 | BJ7: 103.98623 | BK7: 111.13204 | BL7: 118.32058 | BM7: 124.91626 | BN7: 129.08606 | BO7: 126.98946
A8: 0117 | B8: 2.7203074 | C8: 278.98477 | D8: 279.4699 | E8: 280.4895 | F8: 287.91269 | G8: 287.91666 | H8: 274.82278 | I8: 265.94245 | J8: 262.43008 | K8: 258.17675 | L8: 261.61268 | M8: 261.51853 | N8: 259.97758 | O8: 270.08886 | P8: 283.55538 | Q8: 290.1481 | R8: 306.52837 | S8: 304.20689 | T8: 300.10311 | U8: 294.87118 | V8: 292.26618 | W8: 277.85617 | X8: 266.07314 | Y8: 267.05551 | Z8: 288.00446 | AA8: 298.32418 | AB8: 294.51424 | AC8: 286.25124 | AD8: 284.66281 | AE8: 293.93724 | AF8: 301.78255 | AG8: 306.27644 | AH8: 300.0895 | AI8: 303.4179 | AJ8: 303.65308 | AK8: 299.72225 | AL8: 301.90284 | AM8: 311.28228 | AN8: 310.24111 | AO8: 298.52555 | AP8: 295.21919 | AQ8: 294.62485 | AR8: 293.95303 | AS8: 294.49223 | AT8: 290.8134 | AU8: 293.69416 | AV8: 299.94399 | AW8: 291.42657 | AX8: 284.96492 | AY8: 288.45185 | AZ8: 287.14936 | BA8: 294.07875 | BB8: 293.60159 | BC8: 302.43854 | BD8: 299.37646 | BE8: 302.39706 | BF8: 300.67247 | BG8: 300.89596 | BH8: 277.36193 | BI8: 270.06913 | BJ8: 274.30882 | BK8: 282.21003 | BL8: 278.83281 | BM8: 286.58608 | BN8: 305.03821 | BO8: 326.86467
A9: 0118 | B9: 1.1149506 | C9: 112.4398 | D9: 112.2271 | E9: 112.46501 | F9: 112.71338 | G9: 112.83702 | H9: 112.95649 | I9: 112.53032 | J9: 112.21973 | K9: 111.33835 | L9: 110.62252 | M9: 110.47268 | N9: 110.79272 | O9: 112.72722 | P9: 115.74888 | Q9: 117.11006 | R9: 118.3165 | S9: 120.61897 | T9: 121.74198 | U9: 122.36239 | V9: 124.11086 | W9: 124.2625 | X9: 123.78699 | Y9: 124.81727 | Z9: 127.26983 | AA9: 129.81118 | AB9: 130.4167 | AC9: 129.58654 | AD9: 129.05432 | AE9: 129.85592 | AF9: 129.54959 | AG9: 129.03042 | AH9: 129.18362 | AI9: 129.58415 | AJ9: 129.79722 | AK9: 131.28318 | AL9: 132.72831 | AM9: 134.64705 | AN9: 134.98987 | AO9: 134.64951 | AP9: 134.9344 | AQ9: 135.11098 | AR9: 135.22246 | AS9: 134.39375 | AT9: 133.98436 | AU9: 132.37216 | AV9: 130.1772 | AW9: 128.2567 | AX9: 128.55814 | AY9: 127.97816 | AZ9: 127.17557 | BA9: 125.87128 | BB9: 127.21744 | BC9: 127.95145 | BD9: 128.45338 | BE9: 128.11897 | BF9: 127.81099 | BG9: 127.91092 | BH9: 126.53334 | BI9: 125.55533 | BJ9: 125.64402 | BK9: 125.746 | BL9: 125.35483 | BM9: 125.40248 | BN9: 125.24627 | BO9: 126.37472
A10: 0119 | B10: 0.44158221 | C10: 44.344376 | D10: 44.48142 | E10: 44.61486 | F10: 44.550249 | G10: 44.471086 | H10: 44.553627 | I10: 44.618624 | J10: 44.561245 | K10: 44.790443 | L10: 44.818569 | M10: 44.679879 | N10: 45.039457 | O10: 45.43015 | P10: 45.684242 | Q10: 45.585034 | R10: 45.781436 | S10: 45.796838 | T10: 45.856154 | U10: 45.456589 | V10: 45.342644 | W10: 45.609853 | X10: 45.805549 | Y10: 45.583618 | Z10: 45.829234 | AA10: 46.68248 | AB10: 46.769338 | AC10: 46.735416 | AD10: 46.745679 | AE10: 47.26075 | AF10: 47.368191 | AG10: 47.148735 | AH10: 47.263434 | AI10: 47.290613 | AJ10: 47.287029 | AK10: 47.096345 | AL10: 47.381591 | AM10: 47.378807 | AN10: 47.755431 | AO10: 47.745018 | AP10: 48.667306 | AQ10: 49.21378 | AR10: 49.55484 | AS10: 49.410118 | AT10: 49.531923 | AU10: 49.801964 | AV10: 49.73892 | AW10: 49.294053 | AX10: 49.408958 | AY10: 50.041224 | AZ10: 50.118729 | BA10: 49.885632 | BB10: 50.112064 | BC10: 49.895548 | BD10: 50.122717 | BE10: 49.427728 | BF10: 49.777162 | BG10: 50.058029 | BH10: 49.978365 | BI10: 49.611661 | BJ10: 50.263161 | BK10: 50.697851 | BL10: 50.891728 | BM10: 50.912997 | BN10: 50.261807 | BO10: 51.186673
A11: 0121 | B11: 0.56435664 | C11: 56.824346 | D11: 56.8468 | E11: 57.257023 | F11: 58.198779 | G11: 58.824047 | H11: 60.776125 | I11: 61.52217 | J11: 61.938044 | K11: 62.036779 | L11: 61.979579 | M11: 62.074696 | N11: 62.399308 | O11: 62.959388 | P11: 63.305019 | Q11: 63.224227 | R11: 63.335648 | S11: 63.632407 | T11: 63.765492 | U11: 64.22908 | V11: 64.918612 | W11: 65.461982 | X11: 65.586757 | Y11: 65.719808 | Z11: 66.442806 | AA11: 67.567066 | AB11: 68.723999 | AC11: 69.201935 | AD11: 69.474256 | AE11: 69.765779 | AF11: 69.840746 | AG11: 70.068803 | AH11: 70.34537 | AI11: 70.506232 | AJ11: 70.90835 | AK11: 71.126124 | AL11: 71.646686 | AM11: 72.114884 | AN11: 72.416995 | AO11: 72.898242 | AP11: 73.382232 | AQ11: 73.426085 | AR11: 73.733154 | AS11: 73.511631 | AT11: 73.782487 | AU11: 73.669441 | AV11: 73.661575 | AW11: 73.494833 | AX11: 73.569266 | AY11: 73.414991 | AZ11: 72.228683 | BA11: 72.212741 | BB11: 71.797235 | BC11: 71.582542 | BD11: 71.095386 | BE11: 71.207032 | BF11: 70.993117 | BG11: 71.165231 | BH11: 70.804687 | BI11: 70.306561 | BJ11: 70.128527 | BK11: 70.568061 | BL11: 70.530859 | BM11: 70.487533 | BN11: 70.281789 | BO11: 70.506594
A12: 0122 | B12: 0.96479383 | C12: 98.015319 | D12: 98.831631 | E12: 99.007089 | F12: 99.16062 | G12: 99.538466 | H12: 102.83304 | I12: 104.1065 | J12: 104.56698 | K12: 104.22433 | L12: 104.17263 | M12: 104.29527 | N12: 104.73825 | O12: 105.46178 | P12: 106.0411 | Q12: 106.53831 | R12: 107.93332 | S12: 108.09042 | T12: 108.60584 | U12: 108.85413 | V12: 109.07489 | W12: 108.68454 | X12: 108.3804 | Y12: 108.4099 | Z12: 108.20521 | AA12: 108.41834 | AB12: 107.7778 | AC12: 108.04112 | AD12: 108.39954 | AE12: 108.51475 | AF12: 108.78748 | AG12: 109.42299 | AH12: 111.7503 | AI12: 114.50013 | AJ12: 115.51686 | AK12: 116.30855 | AL12: 116.4685 | AM12: 116.58155 | AN12: 116.65133 | AO12: 116.75011 | AP12: 116.77865 | AQ12: 118.83963 | AR12: 119.9037 | AS12: 120.35676 | AT12: 120.9432 | AU12: 121.27426 | AV12: 121.64049 | AW12: 121.20237 | AX12: 121.77847 | AY12: 122.39023 | AZ12: 122.02016 | BA12: 123.22478 | BB12: 124.10958 | BC12: 124.10052 | BD12: 124.36593 | BE12: 124.38394 | BF12: 123.97003 | BG12: 124.02042 | BH12: 123.95633 | BI12: 124.522 | BJ12: 124.52732 | BK12: 124.75723 | BL12: 125.15447 | BM12: 124.96027 | BN12: 124.70529 | BO12: 124.92142
A13: 0211 | B13: 0.70259633 | C13: 70.482286 | D13: 71.536454 | E13: 72.683374 | F13: 73.352031 | G13: 73.685657 | H13: 73.55558 | I13: 73.599693 | J13: 74.052972 | K13: 74.432307 | L13: 74.480114 | M13: 74.221581 | N13: 74.123014 | O13: 74.517547 | P13: 75.268507 | Q13: 76.226123 | R13: 76.916707 | S13: 77.234585 | T13: 77.685313 | U13: 77.980094 | V13: 78.250292 | W13: 79.088477 | X13: 79.688606 | Y13: 79.872032 | Z13: 79.757597 | AA13: 80.014491 | AB13: 80.474898 | AC13: 81.159942 | AD13: 81.641753 | AE13: 81.561338 | AF13: 81.423165 | AG13: 81.855555 | AH13: 82.377923 | AI13: 82.559539 | AJ13: 82.701172 | AK13: 82.606376 | AL13: 82.286551 | AM13: 82.504509 | AN13: 83.346078 | AO13: 83.901402 | AP13: 84.07875 | AQ13: 84.679443 | AR13: 84.938032 | AS13: 85.014207 | AT13: 85.542252 | AU13: 86.262956 | AV13: 86.414185 | AW13: 86.002667 | AX13: 85.471817 | AY13: 85.291806 | AZ13: 85.929588 | BA13: 86.770915 | BB13: 87.403019 | BC13: 87.793596 | BD13: 87.969382 | BE13: 88.119989 | BF13: 88.264577 | BG13: 88.644064 | BH13: 88.823442 | BI13: 88.66249 | BJ13: 88.102 | BK13: 88.332301 | BL13: 89.21683 | BM13: 89.605931 | BN13: 89.899429 | BO13: 90.145706
... A76: 1270 | B76: 0.12982936 | C76: 13.031095 | D76: 13.048322 | E76: 13.13652 | F76: 13.197155 | G76: 13.234047 | H76: 13.258228 | I76: 13.251363 | J76: 13.23411 | K76: 13.185962 | L76: 13.151639 | M76: 13.116403 | N76: 13.141057 | O76: 13.106107 | P76: 13.066072 | Q76: 12.999579 | R76: 12.984958 | S76: 12.973406 | T76: 12.978206 | U76: 12.989168 | V76: 12.983341 | W76: 12.94122 | X76: 12.9415 | Y76: 12.922288 | Z76: 12.93874 | AA76: 12.904955 | AB76: 12.90323 | AC76: 12.91403 | AD76: 12.872626 | AE76: 12.852601 | AF76: 12.799759 | AG76: 12.803212 | AH76: 12.826142 | AI76: 12.840731 | AJ76: 12.87683 | AK76: 12.874466 | AL76: 12.842819 | AM76: 12.810688 | AN76: 12.801743 | AO76: 12.779968 | AP76: 12.798682 | AQ76: 12.77664 | AR76: 12.775589 | AS76: 12.728314 | AT76: 12.722692 | AU76: 12.695424 | AV76: 12.704003 | AW76: 12.68788 | AX76: 12.692057 | AY76: 12.671619 | AZ76: 12.662377 | BA76: 12.642704 | BB76: 12.700899 | BC76: 12.741144 | BD76: 12.775849 | BE76: 12.727147 | BF76: 12.71851 | BG76: 12.701407 | BH76: 12.760846 | BI76: 12.776926 | BJ76: 12.790962 | BK76: 12.778098 | BL76: 12.787656 | BM76: 12.837389 | BN76: 12.808709 | BO76: 12.830163
A77: (en blanco) | C77: 10260.111 | D77: 10345.991 | E77: 10397.607 | F77: 10431.063 | G77: 10432.471 | H77: 10426.626 | I77: 10422.571 | J77: 10427.167 | K77: 10415.742 | L77: 10402.442 | M77: 10395.611 | N77: 10404.184 | O77: 10475.535 | P77: 10562.319 | Q77: 10588.872 | R77: 10637.624 | S77: 10648.611 | T77: 10660.717 | U77: 10656.225 | V77: 10668.185 | W77: 10653.704 | X77: 10644.306 | Y77: 10664.96 | Z77: 10734.124 | AA77: 10831.638 | AB77: 10896.907 | AC77: 10926.28 | AD77: 10939.302 | AE77: 10970.459 | AF77: 11005.335 | AG77: 11020.628 | AH77: 11017.215 | AI77: 11051.231 | AJ77: 11072.202 | AK77: 11087.609 | AL77: 11134.055 | AM77: 11215.413 | AN77: 11283.913 | AO77: 11297.687 | AP77: 11313.997 | AQ77: 11347.944 | AR77: 11357.339 | AS77: 11354.886 | AT77: 11359.543 | AU77: 11392.068 | AV77: 11410.681 | AW77: 11395.081 | AX77: 11405.208 | AY77: 11439.193 | AZ77: 11489.999 | BA77: 11513.639 | BB77: 11542.761 | BC77: 11574.932 | BD77: 11602.114 | BE77: 11607.322 | BF77: 11617.003 | BG77: 11651.03 | BH77: 11620.787 | BI77: 11595.658 | BJ77: 11626.219 | BK77: 11682.752 | BL77: 11756.442 | BM77: 11802.785 | BN77: 11856.808 | BO77: 11914.166
A78: Total general | B78: 100 | C78: 20319.044 | D78: 20489.12 | E78: 20591.339 | F78: 20657.596 | G78: 20660.384 | H78: 20648.808 | I78: 20640.779 | J78: 20649.88 | K78: 20627.254 | L78: 20600.914 | M78: 20587.387 | N78: 20604.365 | O78: 20745.668 | P78: 20917.534 | Q78: 20970.119 | R78: 21066.668 | S78: 21088.425 | T78: 21112.401 | U78: 21103.504 | V78: 21127.189 | W78: 21098.512 | X78: 21079.901 | Y78: 21120.802 | Z78: 21257.775 | AA78: 21450.891 | AB78: 21580.148 | AC78: 21638.32 | AD78: 21664.108 | AE78: 21725.81 | AF78: 21794.879 | AG78: 21825.165 | AH78: 21818.406 | AI78: 21885.77 | AJ78: 21927.302 | AK78: 21957.814 | AL78: 22049.795 | AM78: 22210.916 | AN78: 22346.573 | AO78: 22373.85 | AP78: 22406.152 | AQ78: 22473.38 | AR78: 22491.985 | AS78: 22487.128 | AT78: 22496.35 | AU78: 22560.763 | AV78: 22597.623 | AW78: 22566.729 | AX78: 22586.783 | AY78: 22654.089 | AZ78: 22754.704 | BA78: 22801.52 | BB78: 22859.193 | BC78: 22922.905 | BD78: 22976.736 | BE78: 22987.049 | BF78: 23006.221 | BG78: 23073.609 | BH78: 23013.715 | BI78: 22963.949 | BJ78: 23024.473 | BK78: 23136.43 | BL78: 23282.366 | BM78: 23374.143 | BN78: 23481.129 | BO78: 23594.722

Sheet agrega a grupo
A1: Grupo | B1: Ponder | C1: 39814 | D1: 39845 | E1: 39873 | F1: 39904 | G1: 39934 | H1: 39965 | I1: 39995 | J1: 40026 | K1: 40057 | L1: 40087 | M1: 40118 | N1: 40148 | O1: 40179 | P1: 40210 | Q1: 40238 | R1: 40269 | S1: 40299 | T1: 40330 | U1: 40360 | V1: 40391 | W1: 40422 | X1: 40452 | Y1: 40483 | Z1: 40513 | AA1: 40544 | AB1: 40575 | AC1: 40603 | AD1: 40634 | AE1: 40664 | AF1: 40695 | AG1: 40725 | AH1: 40756 | AI1: 40787 | AJ1: 40817 | AK1: 40848 | AL1: 40878 | AM1: 40909 | AN1: 40940 | AO1: 40969 | AP1: 41000 | AQ1: 41030 | AR1: 41061 | AS1: 41091 | AT1: 41122 | AU1: 41153 | AV1: 41183 | AW1: 41214 | AX1: 41244 | AY1: 41275 | AZ1: 41306 | BA1: 41334 | BB1: 41365 | BC1: 41395 | BD1: 41426 | BE1: 41456 | BF1: 41487 | BG1: 41518 | BH1: 41548 | BI1: 41579 | BJ1: 41609 | BK1: 41640 | BL1: 41671 | BM1: 41699 | BN1: 41730 | BO1: 41760
A2: 011 | B2: 3.7509189 | C2: =+#REF!*'agrega a grupo'!$B2 -> #REF! | D2: =+#REF!*'agrega a grupo'!$B2 -> #REF! | E2: =+#REF!*'agrega a grupo'!$B2 -> #REF! | F2: =+#REF!*'agrega a grupo'!$B2 -> #REF! | G2: =+#REF!*'agrega a grupo'!$B2 -> #REF! | H2: =+#REF!*'agrega a grupo'!$B2 -> #REF! | I2: =+#REF!*'agrega a grupo'!$B2 -> #REF! | J2: =+#REF!*'agrega a grupo'!$B2 -> #REF! | ... BO2: =+#REF!*'agrega a grupo'!$B2 -> #REF!
A3: 011 | B3: 4.7769854 | C3: =+#REF!*'agrega a grupo'!$B3 -> #REF! | D3: =+#REF!*'agrega a grupo'!$B3 -> #REF! | E3: =+#REF!*'agrega a grupo'!$B3 -> #REF! | F3: =+#REF!*'agrega a grupo'!$B3 -> #REF! | G3: =+#REF!*'agrega a grupo'!$B3 -> #REF! | H3: =+#REF!*'agrega a grupo'!$B3 -> #REF! | I3: =+#REF!*'agrega a grupo'!$B3 -> #REF! | J3: =+#REF!*'agrega a grupo'!$B3 -> #REF! | ... BO3: =+#REF!*'agrega a grupo'!$B3 -> #REF!
A4: 011 | B4: 0.60482878 | C4: =+#REF!*'agrega a grupo'!$B4 -> #REF! | D4: =+#REF!*'agrega a grupo'!$B4 -> #REF! | E4: =+#REF!*'agrega a grupo'!$B4 -> #REF! | F4: =+#REF!*'agrega a grupo'!$B4 -> #REF! | G4: =+#REF!*'agrega a grupo'!$B4 -> #REF! | H4: =+#REF!*'agrega a grupo'!$B4 -> #REF! | I4: =+#REF!*'agrega a grupo'!$B4 -> #REF! | J4: =+#REF!*'agrega a grupo'!$B4 -> #REF! | ... BO4: =+#REF!*'agrega a grupo'!$B4 -> #REF!
A5: 011 | B5: 3.2817273 | C5: =+#REF!*'agrega a grupo'!$B5 -> #REF! | D5: =+#REF!*'agrega a grupo'!$B5 -> #REF! | E5: =+#REF!*'agrega a grupo'!$B5 -> #REF! | F5: =+#REF!*'agrega a grupo'!$B5 -> #REF! | G5: =+#REF!*'agrega a grupo'!$B5 -> #REF! | H5: =+#REF!*'agrega a grupo'!$B5 -> #REF! | I5: =+#REF!*'agrega a grupo'!$B5 -> #REF! | J5: =+#REF!*'agrega a grupo'!$B5 -> #REF! | ... BO5: =+#REF!*'agrega a grupo'!$B5 -> #REF!
A6: 011 | B6: 1.024325 | C6: =+#REF!*'agrega a grupo'!$B6 -> #REF! | D6: =+#REF!*'agrega a grupo'!$B6 -> #REF! | E6: =+#REF!*'agrega a grupo'!$B6 -> #REF! | F6: =+#REF!*'agrega a grupo'!$B6 -> #REF! | G6: =+#REF!*'agrega a grupo'!$B6 -> #REF! | H6: =+#REF!*'agrega a grupo'!$B6 -> #REF! | I6: =+#REF!*'agrega a grupo'!$B6 -> #REF! | J6: =+#REF!*'agrega a grupo'!$B6 -> #REF! | ... BO6: =+#REF!*'agrega a grupo'!$B6 -> #REF!
A7: 011 | B7: 0.89582886 | C7: =+#REF!*'agrega a grupo'!$B7 -> #REF! | D7: =+#REF!*'agrega a grupo'!$B7 -> #REF! | E7: =+#REF!*'agrega a grupo'!$B7 -> #REF! | F7: =+#REF!*'agrega a grupo'!$B7 -> #REF! | G7: =+#REF!*'agrega a grupo'!$B7 -> #REF! | H7: =+#REF!*'agrega a grupo'!$B7 -> #REF! | I7: =+#REF!*'agrega a grupo'!$B7 -> #REF! | J7: =+#REF!*'agrega a grupo'!$B7 -> #REF! | ... BO7: =+#REF!*'agrega a grupo'!$B7 -> #REF!
A8: 011 | B8: 2.7203074 | C8: =+#REF!*'agrega a grupo'!$B8 -> #REF! | D8: =+#REF!*'agrega a grupo'!$B8 -> #REF! | E8: =+#REF!*'agrega a grupo'!$B8 -> #REF! | F8: =+#REF!*'agrega a grupo'!$B8 -> #REF! | G8: =+#REF!*'agrega a grupo'!$B8 -> #REF! | H8: =+#REF!*'agrega a grupo'!$B8 -> #REF! | I8: =+#REF!*'agrega a grupo'!$B8 -> #REF! | J8: =+#REF!*'agrega a grupo'!$B8 -> #REF! | ... BO8: =+#REF!*'agrega a grupo'!$B8 -> #REF!
A9: 011 | B9: 1.1149506 | C9: =+#REF!*'agrega a grupo'!$B9 -> #REF! | D9: =+#REF!*'agrega a grupo'!$B9 -> #REF! | E9: =+#REF!*'agrega a grupo'!$B9 -> #REF! | F9: =+#REF!*'agrega a grupo'!$B9 -> #REF! | G9: =+#REF!*'agrega a grupo'!$B9 -> #REF! | H9: =+#REF!*'agrega a grupo'!$B9 -> #REF! | I9: =+#REF!*'agrega a grupo'!$B9 -> #REF! | J9: =+#REF!*'agrega a grupo'!$B9 -> #REF! | ... BO9: =+#REF!*'agrega a grupo'!$B9 -> #REF!
A10: 011 | B10: 0.44158221 | C10: =+#REF!*'agrega a grupo'!$B10 -> #REF! | D10: =+#REF!*'agrega a grupo'!$B10 -> #REF! | E10: =+#REF!*'agrega a grupo'!$B10 -> #REF! | F10: =+#REF!*'agrega a grupo'!$B10 -> #REF! | G10: =+#REF!*'agrega a grupo'!$B10 -> #REF! | H10: =+#REF!*'agrega a grupo'!$B10 -> #REF! | I10: =+#REF!*'agrega a grupo'!$B10 -> #REF! | J10: =+#REF!*'agrega a grupo'!$B10 -> #REF! | ... BO10: =+#REF!*'agrega a grupo'!$B10 -> #REF!
A11: 012 | B11: 0.56435664 | C11: =+#REF!*'agrega a grupo'!$B11 -> #REF! | D11: =+#REF!*'agrega a grupo'!$B11 -> #REF! | E11: =+#REF!*'agrega a grupo'!$B11 -> #REF! | F11: =+#REF!*'agrega a grupo'!$B11 -> #REF! | G11: =+#REF!*'agrega a grupo'!$B11 -> #REF! | H11: =+#REF!*'agrega a grupo'!$B11 -> #REF! | I11: =+#REF!*'agrega a grupo'!$B11 -> #REF! | J11: =+#REF!*'agrega a grupo'!$B11 -> #REF! | ... BO11: =+#REF!*'agrega a grupo'!$B11 -> #REF!
A12: 012 | B12: 0.96479383 | C12: =+#REF!*'agrega a grupo'!$B12 -> #REF! | D12: =+#REF!*'agrega a grupo'!$B12 -> #REF! | E12: =+#REF!*'agrega a grupo'!$B12 -> #REF! | F12: =+#REF!*'agrega a grupo'!$B12 -> #REF! | G12: =+#REF!*'agrega a grupo'!$B12 -> #REF! | H12: =+#REF!*'agrega a grupo'!$B12 -> #REF! | I12: =+#REF!*'agrega a grupo'!$B12 -> #REF! | J12: =+#REF!*'agrega a grupo'!$B12 -> #REF! | ... BO12: =+#REF!*'agrega a grupo'!$B12 -> #REF!
A13: 021 | B13: 0.70259633 | C13: =+#REF!*'agrega a grupo'!$B13 -> #REF! | D13: =+#REF!*'agrega a grupo'!$B13 -> #REF! | E13: =+#REF!*'agrega a grupo'!$B13 -> #REF! | F13: =+#REF!*'agrega a grupo'!$B13 -> #REF! | G13: =+#REF!*'agrega a grupo'!$B13 -> #REF! | H13: =+#REF!*'agrega a grupo'!$B13 -> #REF! | I13: =+#REF!*'agrega a grupo'!$B13 -> #REF! | J13: =+#REF!*'agrega a grupo'!$B13 -> #REF! | ... BO13: =+#REF!*'agrega a grupo'!$B13 -> #REF!
... A76: 127 | B76: 0.12982936 | C76: =+#REF!*'agrega a grupo'!$B76 -> #REF! | D76: =+#REF!*'agrega a grupo'!$B76 -> #REF! | E76: =+#REF!*'agrega a grupo'!$B76 -> #REF! | F76: =+#REF!*'agrega a grupo'!$B76 -> #REF! | G76: =+#REF!*'agrega a grupo'!$B76 -> #REF! | H76: =+#REF!*'agrega a grupo'!$B76 -> #REF! | I76: =+#REF!*'agrega a grupo'!$B76 -> #REF! | J76: =+#REF!*'agrega a grupo'!$B76 -> #REF! | ... BO76: =+#REF!*'agrega a grupo'!$B76 -> #REF!

Sheet Agrega a g suma
B1: Etiquetas de fila | C1: Suma de Ponder | D1: Suma de ene-09 | E1: Suma de feb-09 | F1: Suma de mar-09 | G1: Suma de abr-09 | H1: Suma de may-09 | I1: Suma de jun-09 | J1: Suma de jul-09 | K1: Suma de ago-09 | L1: Suma de sep-09 | M1: Suma de oct-09 | N1: Suma de nov-09 | O1: Suma de dic-09 | P1: Suma de ene-10 | Q1: Suma de feb-10 | R1: Suma de mar-10 | S1: Suma de abr-10 | T1: Suma de may-10 | U1: Suma de jun-10 | V1: Suma de jul-10 | W1: Suma de ago-10 | X1: Suma de sep-10 | Y1: Suma de oct-10 | Z1: Suma de nov-10 | AA1: Suma de dic-10 | AB1: Suma de ene-11 | AC1: Suma de feb-11 | AD1: Suma de mar-11 | AE1: Suma de abr-11 | AF1: Suma de may-11 | AG1: Suma de jun-11 | AH1: Suma de jul-11 | AI1: Suma de ago-11 | AJ1: Suma de sep-11 | AK1: Suma de oct-11 | AL1: Suma de nov-11 | AM1: Suma de dic-11 | AN1: Suma de ene-12 | AO1: Suma de feb-12 | AP1: Suma de mar-12 | AQ1: Suma de abr-12 | AR1: Suma de may-12 | AS1: Suma de jun-12 | AT1: Suma de jul-12 | AU1: Suma de ago-12 | AV1: Suma de sep-12 | AW1: Suma de oct-12 | AX1: Suma de nov-12 | AY1: Suma de dic-12 | AZ1: Suma de ene-13 | BA1: Suma de feb-13 | BB1: Suma de mar-13 | BC1: Suma de abr-13 | BD1: Suma de may-13 | BE1: Suma de jun-13 | BF1: Suma de jul-13 | BG1: Suma de ago-13 | BH1: Suma de sep-13 | BI1: Suma de oct-13 | BJ1: Suma de nov-13 | BK1: Suma de dic-13 | BL1: Suma de ene-14 | BM1: Suma de feb-14 | BN1: Suma de mar-14 | BO1: Suma de abr-14 | BP1: Suma de may-14
A2: =+LEFT(B2,2) -> 01 | B2: 011 | C2: 18.611454 | D2: 1878.7524 | E2: 1885.4108 | F2: 1887.6138 | G2: 1897.503 | H2: 1893.8442 | I2: 1869.2656 | J2: 1850.2298 | K2: 1845.1208 | L2: 1830.1983 | M2: 1818.6193 | N2: 1804.7368 | O2: 1800.2047 | P2: 1812.8304 | Q2: 1839.9448 | R2: 1852.1411 | S2: 1878.9265 | T2: 1874.5445 | U2: 1868.349 | V2: 1856.2316 | W2: 1852.6827 | X2: 1835.2063 | Y2: 1821.4706 | Z2: 1827.2646 | AA2: 1869.4622 | AB2: 1902.5899 | AC2: 1913.7413 | AD2: 1913.4157 | AE2: 1909.9411 | AF2: 1929.1685 | AG2: 1937.5565 | AH2: 1943.6967 | AI2: 1933.9332 | AJ2: 1942.9465 | AK2: 1953.0996 | AL2: 1949.6027 | AM2: 1960.8638 | AN2: 1983.6975 | AO2: 1990.8855 | AP2: 1984.454 | AQ2: 1994.1009 | AR2: 2004.7271 | AS2: 1999.8216 | AT2: 1995.3529 | AU2: 1993.6408 | AV2: 1995.8217 | AW2: 2004.1386 | AX2: 1987.1862 | AY2: 1985.4309 | AZ2: 1992.4894 | BA2: 1988.5263 | BB2: 1992.1063 | BC2: 2006.0558 | BD2: 2009.9614 | BE2: 2006.3618 | BF2: 2011.9352 | BG2: 2014.9714 | BH2: 2024.1246 | BI2: 1993.3058 | BJ2: 1976.5162 | BK2: 1981.2084 | BL2: 1998.7281 | BM2: 2005.081 | BN2: 2022.0459 | BO2: 2046.199 | BP2: 2080.2774
A3: =+LEFT(B3,2) -> 01 | B3: 012 | C3: 1.5291505 | D3: 154.83966 | E3: 155.67843 | F3: 156.26411 | G3: 157.3594 | H3: 158.36251 | I3: 163.60916 | J3: 165.62867 | K3: 166.50503 | L3: 166.26111 | M3: 166.15221 | N3: 166.36996 | O3: 167.13755 | P3: 168.42117 | Q3: 169.34612 | R3: 169.76254 | S3: 171.26897 | T3: 171.72283 | U3: 172.37133 | V3: 173.08321 | W3: 173.9935 | X3: 174.14653 | Y3: 173.96715 | Z3: 174.12971 | AA3: 174.64801 | AB3: 175.9854 | AC3: 176.5018 | AD3: 177.24306 | AE3: 177.8738 | AF3: 178.28053 | AG3: 178.62823 | AH3: 179.49179 | AI3: 182.09567 | AJ3: 185.00637 | AK3: 186.42521 | AL3: 187.43467 | AM3: 188.11518 | AN3: 188.69643 | AO3: 189.06832 | AP3: 189.64835 | AQ3: 190.16089 | AR3: 192.26571 | AS3: 193.63685 | AT3: 193.86839 | AU3: 194.72569 | AV3: 194.94371 | AW3: 195.30207 | AX3: 194.69721 | AY3: 195.34773 | AZ3: 195.80522 | BA3: 194.24885 | BB3: 195.43752 | BC3: 195.90681 | BD3: 195.68307 | BE3: 195.46132 | BF3: 195.59097 | BG3: 194.96315 | BH3: 195.18565 | BI3: 194.76102 | BJ3: 194.82856 | BK3: 194.65584 | BL3: 195.32529 | BM3: 195.68533 | BN3: 195.4478 | BO3: 194.98708 | BP3: 195.42801
A4: =+LEFT(B4,2) -> 02 | B4: 021 | C4: 1.1284053 | D4: 113.34589 | E4: 114.69271 | F4: 116.0282 | G4: 116.66958 | H4: 117.33681 | I4: 117.45422 | J4: 117.46868 | K4: 118.13248 | L4: 118.93512 | M4: 119.4018 | N4: 119.7842 | O4: 120.05683 | P4: 120.921 | Q4: 122.1371 | R4: 123.62466 | S4: 124.49093 | T4: 124.70152 | U4: 125.27562 | V4: 125.7907 | W4: 126.19555 | X4: 127.22864 | Y4: 127.88652 | Z4: 128.26545 | AA4: 128.10674 | AB4: 128.20198 | AC4: 128.86451 | AD4: 129.57965 | AE4: 130.18416 | AF4: 130.29926 | AG4: 130.3501 | AH4: 130.91075 | AI4: 131.38711 | AJ4: 131.45709 | AK4: 131.64269 | AL4: 131.49791 | AM4: 131.08054 | AN4: 131.55014 | AO4: 132.45111 | AP4: 132.93826 | AQ4: 133.14783 | AR4: 133.81113 | AS4: 134.32396 | AT4: 134.61468 | AU4: 135.10261 | AV4: 135.61981 | AW4: 135.68965 | AX4: 135.10522 | AY4: 134.34908 | AZ4: 133.89276 | BA4: 134.59745 | BB4: 135.52412 | BC4: 136.27182 | BD4: 136.69068 | BE4: 136.77837 | BF4: 137.04074 | BG4: 137.04213 | BH4: 137.19725 | BI4: 137.58914 | BJ4: 137.45615 | BK4: 136.74125 | BL4: 137.06337 | BM4: 138.01372 | BN4: 138.35429 | BO4: 138.97181 | BP4: 139.66675
A5: =+LEFT(B5,2) -> 02 | B5: 022 | C5: 0.12425265 | D5: 12.491221 | E5: 12.579147 | F5: 12.675228 | G5: 12.720987 | H5: 12.768604 | I5: 12.83191 | J5: 12.868356 | K5: 12.911086 | L5: 12.916604 | M5: 12.915318 | N5: 12.947193 | O5: 12.963081 | P5: 13.034852 | Q5: 13.194075 | R5: 13.447587 | S5: 13.62416 | T5: 13.723777 | U5: 13.758594 | V5: 13.788974 | W5: 13.986499 | X5: 14.481066 | Y5: 14.667628 | Z5: 14.707947 | AA5: 14.903714 | AB5: 15.078744 | AC5: 15.091715 | AD5: 15.129075 | AE5: 15.157735 | AF5: 15.216948 | AG5: 15.222881 | AH5: 15.196657 | AI5: 15.202277 | AJ5: 15.237245 | AK5: 15.238384 | AL5: 15.253662 | AM5: 15.235875 | AN5: 15.299438 | AO5: 15.412989 | AP5: 15.492837 | AQ5: 15.534811 | AR5: 15.661372 | AS5: 15.71518 | AT5: 15.730647 | AU5: 15.744218 | AV5: 15.77331 | AW5: 15.778444 | AX5: 15.793963 | AY5: 15.798273 | AZ5: 15.828022 | BA5: 15.979821 | BB5: 16.198406 | BC5: 16.262638 | BD5: 16.359128 | BE5: 16.428106 | BF5: 16.455853 | BG5: 16.453526 | BH5: 16.436475 | BI5: 16.444764 | BJ5: 16.474412 | BK5: 16.508667 | BL5: 16.539259 | BM5: 16.614512 | BN5: 16.768081 | BO5: 16.850459 | BP5: 16.95462
A6: =+LEFT(B6,2) -> 03 | B6: 031 | C6: 3.6773191 | D6: 367.29017 | E6: 366.6514 | F6: 367.03264 | G6: 367.17047 | H6: 367.94059 | I6: 368.03484 | J6: 368.25745 | K6: 368.17612 | L6: 367.78715 | M6: 367.32692 | N6: 367.05036 | O6: 367.49794 | P6: 367.36136 | Q6: 366.26886 | R6: 366.05139 | S6: 366.12888 | T6: 366.27492 | U6: 365.52946 | V6: 365.39975 | W6: 364.64249 | X6: 364.13076 | Y6: 363.41711 | Z6: 363.69141 | AA6: 364.07023 | AB6: 364.77514 | AC6: 364.67991 | AD6: 365.23343 | AE6: 365.72097 | AF6: 366.49886 | AG6: 366.83106 | AH6: 367.19958 | AI6: 367.11951 | AJ6: 367.45031 | AK6: 367.89374 | AL6: 368.29921 | AM6: 368.40572 | AN6: 368.60245 | AO6: 368.53506 | AP6: 368.96853 | AQ6: 369.3924 | AR6: 369.95414 | AS6: 370.09188 | AT6: 370.43907 | AU6: 370.4724 | AV6: 370.64063 | AW6: 370.99066 | AX6: 371.33981 | AY6: 371.79919 | AZ6: 371.84436 | BA6: 371.71944 | BB6: 371.86364 | BC6: 371.96986 | BD6: 372.59764 | BE6: 373.07566 | BF6: 373.29353 | BG6: 372.87154 | BH6: 372.92065 | BI6: 373.22668 | BJ6: 374.53596 | BK6: 375.091 | BL6: 375.50839 | BM6: 375.94197 | BN6: 376.63306 | BO6: 377.36735 | BP6: 378.18955
A7: =+LEFT(B7,2) -> 03 | B7: 032 | C7: 1.2786515 | D7: 127.75386 | E7: 127.59963 | F7: 127.51614 | G7: 127.64297 | H7: 127.71427 | I7: 127.60707 | J7: 127.22491 | K7: 126.80318 | L7: 126.72649 | M7: 126.67408 | N7: 126.79486 | O7: 126.1672 | P7: 126.0284 | Q7: 125.84111 | R7: 125.27699 | S7: 124.97226 | T7: 124.54048 | U7: 124.25002 | V7: 124.1489 | W7: 123.7772 | X7: 123.32853 | Y7: 123.09289 | Z7: 123.37503 | AA7: 123.39105 | AB7: 123.35429 | AC7: 123.08148 | AD7: 122.77765 | AE7: 122.28642 | AF7: 122.31055 | AG7: 121.8616 | AH7: 121.78046 | AI7: 121.79239 | AJ7: 121.64478 | AK7: 121.47274 | AL7: 121.4033 | AM7: 121.59698 | AN7: 121.563 | AO7: 121.50204 | AP7: 121.58494 | AQ7: 121.36851 | AR7: 121.53535 | AS7: 121.57966 | AT7: 121.63594 | AU7: 121.45871 | AV7: 121.46535 | AW7: 121.74866 | AX7: 122.05755 | AY7: 122.09435 | AZ7: 122.31863 | BA7: 122.36778 | BB7: 122.61409 | BC7: 122.37446 | BD7: 122.75477 | BE7: 122.7926 | BF7: 123.04148 | BG7: 122.98041 | BH7: 123.01728 | BI7: 123.24301 | BJ7: 123.40132 | BK7: 123.77943 | BL7: 124.03894 | BM7: 124.23875 | BN7: 124.4559 | BO7: 124.72483 | BP7: 125.00404
A8: =+LEFT(B8,2) -> 04 | B8: 041 | C8: 7.3233942 | D8: 735.13223 | E8: 739.08762 | F8: 742.44015 | G8: 742.95834 | H8: 745.60456 | I8: 748.76232 | J8: 750.62884 | K8: 754.10156 | L8: 756.53455 | M8: 759.12081 | N8: 760.60118 | O8: 762.33145 | P8: 765.30313 | Q8: 768.47289 | R8: 770.96743 | S8: 773.2928 | T8: 776.33055 | U8: 778.6069 | V8: 779.84908 | W8: 781.84764 | X8: 783.66058 | Y8: 785.44059 | Z8: 786.44431 | AA8: 787.58002 | AB8: 789.92025 | AC8: 793.11591 | AD8: 795.35239 | AE8: 797.8527 | AF8: 801.09553 | AG8: 804.52289 | AH8: 806.25522 | AI8: 807.82736 | AJ8: 809.94985 | AK8: 811.53608 | AL8: 813.67284 | AM8: 815.44506 | AN8: 818.30453 | AO8: 821.57695 | AP8: 824.35512 | AQ8: 827.34956 | AR8: 831.25991 | AS8: 835.18179 | AT8: 837.04891 | AU8: 838.75669 | AV8: 841.58544 | AW8: 843.90528 | AX8: 845.60433 | AY8: 847.43261 | AZ8: 849.97475 | BA8: 853.78265 | BB8: 857.02988 | BC8: 859.68231 | BD8: 862.6444 | BE8: 866.59174 | BF8: 869.23988 | BG8: 871.1017 | BH8: 872.94576 | BI8: 874.95331 | BJ8: 876.63876 | BK8: 878.04727 | BL8: 880.31445 | BM8: 884.57608 | BN8: 887.47388 | BO8: 889.79526 | BP8: 892.06716
